<?xml version="1.0" encoding="utf-8"?>
<!-- This URDF was automatically created by SolidWorks to URDF Exporter! Originally created by Stephen Brawner (brawner@gmail.com) 
     Commit Version: 1.6.0-4-g7f85cfe  Build Version: 1.6.7995.38578
     For more information, please see http://wiki.ros.org/sw_urdf_exporter -->
<robot
  xmlns:xacro="http://www.ros.org/wiki/xacro" name="historia">


<!-- Import all Gazebo-customization elements-->
  <xacro:include filename="$(find historia)/urdf/mybot.gazebo" />


   <!-- dummy link -->
        <link name="base_footprint"/>
        <joint name="dummy_joint" type="fixed">
          <origin xyz="0.0 0.0 0.0" rpy="0.0 0.0 0.0"/>
          <parent link="base_footprint"/>
          <child link="base_link"/>
          <axis xyz="0.0 0.0 0.0"/>
          <limit lower="0.0" upper="0.0" effort="0.0" velocity="0.0"/>
        </joint>


  <link
    name="base_link">
    <inertial>
      <origin
        xyz="0.054871 0.00038249 0.08412"
        rpy="0 0 0" />
      <mass
        value="61.491" />
      <inertia
        ixx="6.7839"
        ixy="0.00011592"
        ixz="0.58366"
        iyy="21.073"
        iyz="-0.014273"
        izz="21.196" />
    </inertial>
    <visual>
      <origin
        xyz="0 0 0"
        rpy="0 0 0" />
      <geometry>
        <mesh
          filename="package://historia/meshes/base_link.STL" />
      </geometry>
      <material
        name="">
        <color
          rgba="0.79216 0.81961 0.93333 1" />
      </material>
    </visual>
    <collision>
      <origin
        xyz="0 0 0"
        rpy="0 0 0" />
      <geometry>
        <mesh
          filename="package://historia/meshes/base_link.STL" />
      </geometry>
    </collision>
  </link>
  <link
    name="front_right_wheel_link">
    <inertial>
      <origin
        xyz="-1.5543E-15 0.085 2.4425E-15"
        rpy="0 0 0" />
      <mass
        value="27.504" />
      <inertia
        ixx="0.43066"
        ixy="3.2489E-18"
        ixz="-7.2388E-18"
        iyy="0.73819"
        iyz="-7.1284E-20"
        izz="0.43066" />
    </inertial>
    <visual>
      <origin
        xyz="0 0 0"
        rpy="0 0 0" />
      <geometry>
        <mesh
          filename="package://historia/meshes/front_right_wheel_link.STL" />
      </geometry>
      <material
        name="">
        <color
          rgba="0.79216 0.81961 0.93333 1" />
      </material>
    </visual>
    <collision>
      <origin
        xyz="0 0 0"
        rpy="0 0 0" />
      <geometry>
        <mesh
          filename="package://historia/meshes/front_right_wheel_link.STL" />
      </geometry>
    </collision>
  </link>
  <joint
    name="front_right_wheel_joint"
    type="continuous">
    <origin
      xyz="1.0431 -0.50032 0.061"
      rpy="0 0 0" />
    <parent
      link="base_link" />
    <child
      link="front_right_wheel_link" />
    <axis
      xyz="0 1 0" />
    <limit
      effort="100"
      velocity="0" />
  </joint>
  <link
    name="front_left_wheel_link">
    <inertial>
      <origin
        xyz="0 -0.085 -2.2204E-16"
        rpy="0 0 0" />
      <mass
        value="27.504" />
      <inertia
        ixx="0.43066"
        ixy="-4.4685E-18"
        ixz="-1.4459E-18"
        iyy="0.73819"
        iyz="-2.0771E-19"
        izz="0.43066" />
    </inertial>
    <visual>
      <origin
        xyz="0 0 0"
        rpy="0 0 0" />
      <geometry>
        <mesh
          filename="package://historia/meshes/front_left_wheel_link.STL" />
      </geometry>
      <material
        name="">
        <color
          rgba="0.79216 0.81961 0.93333 1" />
      </material>
    </visual>
    <collision>
      <origin
        xyz="0 0 0"
        rpy="0 0 0" />
      <geometry>
        <mesh
          filename="package://historia/meshes/front_left_wheel_link.STL" />
      </geometry>
    </collision>
  </link>
  <joint
    name="front_left_wheel_joint"
    type="continuous">
    <origin
      xyz="1.0431 0.49993 0.061"
      rpy="0 0 0" />
    <parent
      link="base_link" />
    <child
      link="front_left_wheel_link" />
    <axis
      xyz="0 1 0" />
    <limit
      effort="100"
      velocity="0" />
  </joint>
  <link
    name="rear_left_wheel_link">
    <inertial>
      <origin
        xyz="0 -0.12 0"
        rpy="0 0 0" />
      <mass
        value="48.005" />
      <inertia
        ixx="1.0037"
        ixy="1.236E-17"
        ixz="-1.7355E-18"
        iyy="1.5955"
        iyz="-1.9651E-19"
        izz="1.0037" />
    </inertial>
    <visual>
      <origin
        xyz="0 0 0"
        rpy="0 0 0" />
      <geometry>
        <mesh
          filename="package://historia/meshes/rear_left_wheel_link.STL" />
      </geometry>
      <material
        name="">
        <color
          rgba="0.79216 0.81961 0.93333 1" />
      </material>
    </visual>
    <collision>
      <origin
        xyz="0 0 0"
        rpy="0 0 0" />
      <geometry>
        <mesh
          filename="package://historia/meshes/rear_left_wheel_link.STL" />
      </geometry>
    </collision>
  </link>
  <joint
    name="rear_left_wheel_joint"
    type="continuous">
    <origin
      xyz="-1.0569 0.5001 0.091"
      rpy="0 0 0" />
    <parent
      link="base_link" />
    <child
      link="rear_left_wheel_link" />
    <axis
      xyz="0 1 0" />
    <limit
      effort="100"
      velocity="0" />
  </joint>
  <link
    name="rear_right_wheel_link">
    <inertial>
      <origin
        xyz="0 0.12 0"
        rpy="0 0 0" />
      <mass
        value="48.005" />
      <inertia
        ixx="1.0037"
        ixy="-7.1557E-18"
        ixz="8.897E-19"
        iyy="1.5955"
        iyz="1.7889E-18"
        izz="1.0037" />
    </inertial>
    <visual>
      <origin
        xyz="0 0 0"
        rpy="0 0 0" />
      <geometry>
        <mesh
          filename="package://historia/meshes/rear_right_wheel_link.STL" />
      </geometry>
      <material
        name="">
        <color
          rgba="0.79216 0.81961 0.93333 1" />
      </material>
    </visual>
    <collision>
      <origin
        xyz="0 0 0"
        rpy="0 0 0" />
      <geometry>
        <mesh
          filename="package://historia/meshes/rear_right_wheel_link.STL" />
      </geometry>
    </collision>
  </link>
  <joint
    name="rear_right_wheel_joint"
    type="continuous">
    <origin
      xyz="-1.0569 -0.50021 0.091"
      rpy="0 0 0" />
    <parent
      link="base_link" />
    <child
      link="rear_right_wheel_link" />
    <axis
      xyz="0 1 0" />
    <limit
      effort="100"
      velocity="0" />
  </joint>
  <link
    name="front_right_steer_link">
    <inertial>
      <origin
        xyz="1.9984E-15 0.05 0"
        rpy="0 0 0" />
      <mass
        value="0.007854" />
      <inertia
        ixx="6.5941E-06"
        ixy="2.6475E-20"
        ixz="-2.7573E-24"
        iyy="9.8175E-08"
        iyz="-3.2033E-24"
        izz="6.5941E-06" />
    </inertial>
    <visual>
      <origin
        xyz="0 0 0"
        rpy="0 0 0" />
      <geometry>
        <mesh
          filename="package://historia/meshes/front_right_steer_link.STL" />
      </geometry>
      <material
        name="">
        <color
          rgba="0.79216 0.81961 0.93333 1" />
      </material>
    </visual>
    <collision>
      <origin
        xyz="0 0 0"
        rpy="0 0 0" />
      <geometry>
        <mesh
          filename="package://historia/meshes/front_right_steer_link.STL" />
      </geometry>
    </collision>
  </link>
  <joint
    name="front_right_steer_joint"
    type="prismatic">
    <origin
      xyz="0.97722 -0.32832 0.051213"
      rpy="0 0 0" />
    <parent
      link="base_link" />
    <child
      link="front_right_steer_link" />
    <axis
      xyz="0 -1 0" />
    <limit
      lower="0"
      upper="0"
      effort="100"
      velocity="0" />
  </joint>
  <link
    name="front_left_steer_link">
    <inertial>
      <origin
        xyz="2.2204E-15 -0.05 0"
        rpy="0 0 0" />
      <mass
        value="0.007854" />
      <inertia
        ixx="6.5941E-06"
        ixy="2.6475E-20"
        ixz="-2.7573E-24"
        iyy="9.8175E-08"
        iyz="-3.2033E-24"
        izz="6.5941E-06" />
    </inertial>
    <visual>
      <origin
        xyz="0 0 0"
        rpy="0 0 0" />
      <geometry>
        <mesh
          filename="package://historia/meshes/front_left_steer_link.STL" />
      </geometry>
      <material
        name="">
        <color
          rgba="0.79216 0.81961 0.93333 1" />
      </material>
    </visual>
    <collision>
      <origin
        xyz="0 0 0"
        rpy="0 0 0" />
      <geometry>
        <mesh
          filename="package://historia/meshes/front_left_steer_link.STL" />
      </geometry>
    </collision>
  </link>
  <joint
    name="front_left_steer_joint"
    type="prismatic">
    <origin
      xyz="0.97722 0.32694 0.051213"
      rpy="0 0 0" />
    <parent
      link="base_link" />
    <child
      link="front_left_steer_link" />
    <axis
      xyz="0 -1 0" />
    <limit
      lower="0"
      upper="0"
      effort="100"
      velocity="0" />
  </joint>
  <link
    name="steering_link">
    <inertial>
      <origin
        xyz="-0.0019279 -9.1558E-05 -0.0012714"
        rpy="0 0 0" />
      <mass
        value="0.32198" />
      <inertia
        ixx="0.0047274"
        ixy="-2.8498E-08"
        ixz="6.2308E-06"
        iyy="0.0019325"
        iyz="3.0079E-08"
        izz="0.0028608" />
    </inertial>
    <visual>
      <origin
        xyz="0 0 0"
        rpy="0 0 0" />
      <geometry>
        <mesh
          filename="package://historia/meshes/steering_link.STL" />
      </geometry>
      <material
        name="">
        <color
          rgba="0.79216 0.81961 0.93333 1" />
      </material>
    </visual>
    <collision>
      <origin
        xyz="0 0 0"
        rpy="0 0 0" />
      <geometry>
        <mesh
          filename="package://historia/meshes/steering_link.STL" />
      </geometry>
    </collision>
  </link>
  <joint
    name="steering_joint"
    type="continuous">
    <origin
      xyz="0.28269 -0.00024936 0.44194"
      rpy="0 0 0" />
    <parent
      link="base_link" />
    <child
      link="steering_link" />
    <axis
      xyz="1 0 0" />
    <limit
      effort="5"
      velocity="0" />
  </joint>
  <link
    name="front_camera_link">
    <inertial>
      <origin
        xyz="-0.015563 0.00050656 -0.0099095"
        rpy="0 0 0" />
      <mass
        value="0.040716" />
      <inertia
        ixx="3.4077E-05"
        ixy="3.9139E-08"
        ixz="-3.218E-07"
        iyy="1.0051E-05"
        iyz="5.4791E-09"
        izz="2.6539E-05" />
    </inertial>
    <visual>
      <origin
        xyz="0 0 0"
        rpy="0 0 0" />
      <geometry>
        <mesh
          filename="package://historia/meshes/front_camera_link.STL" />
      </geometry>
      <material
        name="">
        <color
          rgba="0.59216 0.66667 0.68235 1" />
      </material>
    </visual>
    <collision>
      <origin
        xyz="0 0 0"
        rpy="0 0 0" />
      <geometry>
        <mesh
          filename="package://historia/meshes/front_camera_link.STL" />
      </geometry>
    </collision>
  </link>
  <joint
    name="front_camera_joint"
    type="fixed">
    <origin
      xyz="0.078809 -0.0018233 1.1721"
      rpy="0 0.13963 0" />
    <parent
      link="base_link" />
    <child
      link="front_camera_link" />
    <axis
      xyz="0 0 0" />
  </joint>
  <link
    name="left_camera_link">
    <inertial>
      <origin
        xyz="-0.015563 -0.00049343 -0.0099095"
        rpy="0 0 0" />
      <mass
        value="0.040716" />
      <inertia
        ixx="3.4077E-05"
        ixy="3.914E-08"
        ixz="-3.218E-07"
        iyy="1.0051E-05"
        iyz="5.4805E-09"
        izz="2.6539E-05" />
    </inertial>
    <visual>
      <origin
        xyz="0 0 0"
        rpy="0 0 0" />
      <geometry>
        <mesh
          filename="package://historia/meshes/left_camera_link.STL" />
      </geometry>
      <material
        name="">
        <color
          rgba="0.59216 0.66667 0.68235 1" />
      </material>
    </visual>
    <collision>
      <origin
        xyz="0 0 0"
        rpy="0 0 0" />
      <geometry>
        <mesh
          filename="package://historia/meshes/left_camera_link.STL" />
      </geometry>
    </collision>
  </link>
  <joint
    name="left_camera_joint"
    type="fixed">
    <origin
      xyz="-0.24289 0.38079 1.1267"
      rpy="-0.054791 0.46336 1.584" />
    <parent
      link="base_link" />
    <child
      link="left_camera_link" />
    <axis
      xyz="0 0 0" />
  </joint>
  <link
    name="right_camera_link">
    <inertial>
      <origin
        xyz="-0.015563 0.00050655 -0.0099095"
        rpy="0 0 0" />
      <mass
        value="0.040716" />
      <inertia
        ixx="3.4077E-05"
        ixy="3.9136E-08"
        ixz="-3.218E-07"
        iyy="1.0051E-05"
        iyz="5.4764E-09"
        izz="2.6539E-05" />
    </inertial>
    <visual>
      <origin
        xyz="0 0 0"
        rpy="0 0 0" />
      <geometry>
        <mesh
          filename="package://historia/meshes/right_camera_link.STL" />
      </geometry>
      <material
        name="">
        <color
          rgba="0.59216 0.66667 0.68235 1" />
      </material>
    </visual>
    <collision>
      <origin
        xyz="0 0 0"
        rpy="0 0 0" />
      <geometry>
        <mesh
          filename="package://historia/meshes/right_camera_link.STL" />
      </geometry>
    </collision>
  </link>
  <joint
    name="right_camera_joint"
    type="fixed">
    <origin
      xyz="-0.23874 -0.3803 1.1273"
      rpy="0.053105 0.46353 -1.5874" />
    <parent
      link="base_link" />
    <child
      link="right_camera_link" />
    <axis
      xyz="0 0 0" />
  </joint>
  <link
    name="rear_camera_link">
    <inertial>
      <origin
        xyz="-0.015563 0.00050656 -0.0099095"
        rpy="0 0 0" />
      <mass
        value="0.040716" />
      <inertia
        ixx="3.4077E-05"
        ixy="3.9139E-08"
        ixz="-3.218E-07"
        iyy="1.0051E-05"
        iyz="5.4788E-09"
        izz="2.6539E-05" />
    </inertial>
    <visual>
      <origin
        xyz="0 0 0"
        rpy="0 0 0" />
      <geometry>
        <mesh
          filename="package://historia/meshes/rear_camera_link.STL" />
      </geometry>
      <material
        name="">
        <color
          rgba="0.59216 0.66667 0.68235 1" />
      </material>
    </visual>
    <collision>
      <origin
        xyz="0 0 0"
        rpy="0 0 0" />
      <geometry>
        <mesh
          filename="package://historia/meshes/rear_camera_link.STL" />
      </geometry>
    </collision>
  </link>
  <joint
    name="rear_camera_joint"
    type="fixed">
    <origin
      xyz="-0.52142 0.00022659 1.0812"
      rpy="0 0.12217 -3.1416" />
    <parent
      link="base_link" />
    <child
      link="rear_camera_link" />
    <axis
      xyz="0 0 0" />
  </joint>
  <link
    name="imu_link">
    <inertial>
      <origin
        xyz="-0.0075 4.4409E-16 -1.3323E-15"
        rpy="0 0 0" />
      <mass
        value="0.0015" />
      <inertia
        ixx="2.5E-08"
        ixy="4.7107E-25"
        ixz="1.8363E-22"
        iyy="4.0625E-08"
        iyz="1.1494E-25"
        izz="4.0625E-08" />
    </inertial>
    <visual>
      <origin
        xyz="0 0 0"
        rpy="0 0 0" />
      <geometry>
        <mesh
          filename="package://historia/meshes/imu_link.STL" />
      </geometry>
      <material
        name="">
        <color
          rgba="0.79216 0.81961 0.93333 1" />
      </material>
    </visual>
    <collision>
      <origin
        xyz="0 0 0"
        rpy="0 0 0" />
      <geometry>
        <mesh
          filename="package://historia/meshes/imu_link.STL" />
      </geometry>
    </collision>
  </link>
  <joint
    name="imu_joint"
    type="fixed">
    <origin
      xyz="0.076545 -0.0011601 1.1333"
      rpy="0 0.34907 0" />
    <parent
      link="base_link" />
    <child
      link="imu_link" />
    <axis
      xyz="0 0 0" />
  </joint>
  <link
    name="front_middle_ultra_link">
    <inertial>
      <origin
        xyz="0.0041766 -4.2017E-06 5.2682E-05"
        rpy="0 0 0" />
      <mass
        value="0.0062273" />
      <inertia
        ixx="1.2204E-06"
        ixy="-1.3189E-10"
        ixz="-2.0237E-09"
        iyy="2.3852E-07"
        iyz="1.9966E-10"
        izz="1.1941E-06" />
    </inertial>
    <visual>
      <origin
        xyz="0 0 0"
        rpy="0 0 0" />
      <geometry>
        <mesh
          filename="package://historia/meshes/front_middle_ultra_link.STL" />
      </geometry>
      <material
        name="">
        <color
          rgba="0.79216 0.81961 0.93333 1" />
      </material>
    </visual>
    <collision>
      <origin
        xyz="0 0 0"
        rpy="0 0 0" />
      <geometry>
        <mesh
          filename="package://historia/meshes/front_middle_ultra_link.STL" />
      </geometry>
    </collision>
  </link>
  <joint
    name="front_middle_ultra_joint"
    type="fixed">
    <origin
      xyz="1.2487 -1.1483E-05 0.046191"
      rpy="0 0.034907 0" />
    <parent
      link="base_link" />
    <child
      link="front_middle_ultra_link" />
    <axis
      xyz="0 0 0" />
  </joint>
  <link
    name="front_left_ultra_link">
    <inertial>
      <origin
        xyz="0.0041766 -4.2017E-06 5.2682E-05"
        rpy="0 0 0" />
      <mass
        value="0.0062273" />
      <inertia
        ixx="1.2204E-06"
        ixy="-1.3189E-10"
        ixz="-2.0237E-09"
        iyy="2.3852E-07"
        iyz="1.9966E-10"
        izz="1.1941E-06" />
    </inertial>
    <visual>
      <origin
        xyz="0 0 0"
        rpy="0 0 0" />
      <geometry>
        <mesh
          filename="package://historia/meshes/front_left_ultra_link.STL" />
      </geometry>
      <material
        name="">
        <color
          rgba="0.79216 0.81961 0.93333 1" />
      </material>
    </visual>
    <collision>
      <origin
        xyz="0 0 0"
        rpy="0 0 0" />
      <geometry>
        <mesh
          filename="package://historia/meshes/front_left_ultra_link.STL" />
      </geometry>
    </collision>
  </link>
  <joint
    name="front_left_ultra_joint"
    type="fixed">
    <origin
      xyz="1.2473 0.17031 0.046326"
      rpy="0.087936 0.15096 0.53025" />
    <parent
      link="base_link" />
    <child
      link="front_left_ultra_link" />
    <axis
      xyz="0 0 0" />
  </joint>
  <link
    name="front_right_ultra_link">
    <inertial>
      <origin
        xyz="0.0041766 -4.2017E-06 5.2682E-05"
        rpy="0 0 0" />
      <mass
        value="0.0062273" />
      <inertia
        ixx="1.2204E-06"
        ixy="-1.3189E-10"
        ixz="-2.0237E-09"
        iyy="2.3852E-07"
        iyz="1.9966E-10"
        izz="1.1941E-06" />
    </inertial>
    <visual>
      <origin
        xyz="0 0 0"
        rpy="0 0 0" />
      <geometry>
        <mesh
          filename="package://historia/meshes/front_right_ultra_link.STL" />
      </geometry>
      <material
        name="">
        <color
          rgba="0.79216 0.81961 0.93333 1" />
      </material>
    </visual>
    <collision>
      <origin
        xyz="0 0 0"
        rpy="0 0 0" />
      <geometry>
        <mesh
          filename="package://historia/meshes/front_right_ultra_link.STL" />
      </geometry>
    </collision>
  </link>
  <joint
    name="front_right_ultra_joint"
    type="fixed">
    <origin
      xyz="1.2516 -0.16281 0.045574"
      rpy="-0.087936 0.15096 -0.53025" />
    <parent
      link="base_link" />
    <child
      link="front_right_ultra_link" />
    <axis
      xyz="0 0 0" />
  </joint>
  <link
    name="left_corner_ultra_link">
    <inertial>
      <origin
        xyz="0.0041766 -4.2017E-06 5.2682E-05"
        rpy="0 0 0" />
      <mass
        value="0.0062273" />
      <inertia
        ixx="1.2204E-06"
        ixy="-1.3189E-10"
        ixz="-2.0237E-09"
        iyy="2.3852E-07"
        iyz="1.9966E-10"
        izz="1.1941E-06" />
    </inertial>
    <visual>
      <origin
        xyz="0 0 0"
        rpy="0 0 0" />
      <geometry>
        <mesh
          filename="package://historia/meshes/left_corner_ultra_link.STL" />
      </geometry>
      <material
        name="">
        <color
          rgba="0.79216 0.81961 0.93333 1" />
      </material>
    </visual>
    <collision>
      <origin
        xyz="0 0 0"
        rpy="0 0 0" />
      <geometry>
        <mesh
          filename="package://historia/meshes/left_corner_ultra_link.STL" />
      </geometry>
    </collision>
  </link>
  <joint
    name="left_corner_ultra_joint"
    type="fixed">
    <origin
      xyz="0.55114 0.47313 0.044877"
      rpy="0 0.5236 0.88045" />
    <parent
      link="base_link" />
    <child
      link="left_corner_ultra_link" />
    <axis
      xyz="0 0 0" />
  </joint>
  <link
    name="right_corner_ultra_link">
    <inertial>
      <origin
        xyz="0.0041766 -4.2017E-06 5.2682E-05"
        rpy="0 0 0" />
      <mass
        value="0.0062273" />
      <inertia
        ixx="1.2204E-06"
        ixy="-1.3189E-10"
        ixz="-2.0237E-09"
        iyy="2.3852E-07"
        iyz="1.9966E-10"
        izz="1.1941E-06" />
    </inertial>
    <visual>
      <origin
        xyz="0 0 0"
        rpy="0 0 0" />
      <geometry>
        <mesh
          filename="package://historia/meshes/right_corner_ultra_link.STL" />
      </geometry>
      <material
        name="">
        <color
          rgba="0.79216 0.81961 0.93333 1" />
      </material>
    </visual>
    <collision>
      <origin
        xyz="0 0 0"
        rpy="0 0 0" />
      <geometry>
        <mesh
          filename="package://historia/meshes/right_corner_ultra_link.STL" />
      </geometry>
    </collision>
  </link>
  <joint
    name="right_corner_ultra_joint"
    type="fixed">
    <origin
      xyz="0.54721 -0.47573 0.044877"
      rpy="0 0.5236 -1.0472" />
    <parent
      link="base_link" />
    <child
      link="right_corner_ultra_link" />
    <axis
      xyz="0 0 0" />
  </joint>
  <link
    name="right_middle_ultra_link">
    <inertial>
      <origin
        xyz="0.0041766 -4.2017E-06 5.2682E-05"
        rpy="0 0 0" />
      <mass
        value="0.0062273" />
      <inertia
        ixx="1.2204E-06"
        ixy="-1.3189E-10"
        ixz="-2.0237E-09"
        iyy="2.3852E-07"
        iyz="1.9966E-10"
        izz="1.1941E-06" />
    </inertial>
    <visual>
      <origin
        xyz="0 0 0"
        rpy="0 0 0" />
      <geometry>
        <mesh
          filename="package://historia/meshes/right_middle_ultra_link.STL" />
      </geometry>
      <material
        name="">
        <color
          rgba="0.79216 0.81961 0.93333 1" />
      </material>
    </visual>
    <collision>
      <origin
        xyz="0 0 0"
        rpy="0 0 0" />
      <geometry>
        <mesh
          filename="package://historia/meshes/right_middle_ultra_link.STL" />
      </geometry>
    </collision>
  </link>
  <joint
    name="right_middle_ultra_joint"
    type="fixed">
    <origin
      xyz="-0.11671 -0.4715 0.12175"
      rpy="0 0 -1.5708" />
    <parent
      link="base_link" />
    <child
      link="right_middle_ultra_link" />
    <axis
      xyz="0 0 0" />
  </joint>
  <link
    name="right_rear_ultra_link">
    <inertial>
      <origin
        xyz="0.0041766 -4.2017E-06 5.2682E-05"
        rpy="0 0 0" />
      <mass
        value="0.0062273" />
      <inertia
        ixx="1.2204E-06"
        ixy="-1.3189E-10"
        ixz="-2.0237E-09"
        iyy="2.3852E-07"
        iyz="1.9966E-10"
        izz="1.1941E-06" />
    </inertial>
    <visual>
      <origin
        xyz="0 0 0"
        rpy="0 0 0" />
      <geometry>
        <mesh
          filename="package://historia/meshes/right_rear_ultra_link.STL" />
      </geometry>
      <material
        name="">
        <color
          rgba="0.79216 0.81961 0.93333 1" />
      </material>
    </visual>
    <collision>
      <origin
        xyz="0 0 0"
        rpy="0 0 0" />
      <geometry>
        <mesh
          filename="package://historia/meshes/right_rear_ultra_link.STL" />
      </geometry>
    </collision>
  </link>
  <joint
    name="right_rear_ultra_joint"
    type="fixed">
    <origin
      xyz="-0.36095 -0.39014 0.12564"
      rpy="0 0.2618 -1.5708" />
    <parent
      link="base_link" />
    <child
      link="right_rear_ultra_link" />
    <axis
      xyz="0 0 0" />
  </joint>
  <link
    name="left_rear_ultra_link">
    <inertial>
      <origin
        xyz="0.0041766 -4.2017E-06 5.2682E-05"
        rpy="0 0 0" />
      <mass
        value="0.0062273" />
      <inertia
        ixx="1.2204E-06"
        ixy="-1.3189E-10"
        ixz="-2.0237E-09"
        iyy="2.3852E-07"
        iyz="1.9966E-10"
        izz="1.1941E-06" />
    </inertial>
    <visual>
      <origin
        xyz="0 0 0"
        rpy="0 0 0" />
      <geometry>
        <mesh
          filename="package://historia/meshes/left_rear_ultra_link.STL" />
      </geometry>
      <material
        name="">
        <color
          rgba="0.79216 0.81961 0.93333 1" />
      </material>
    </visual>
    <collision>
      <origin
        xyz="0 0 0"
        rpy="0 0 0" />
      <geometry>
        <mesh
          filename="package://historia/meshes/left_rear_ultra_link.STL" />
      </geometry>
    </collision>
  </link>
  <joint
    name="left_rear_ultra_joint"
    type="fixed">
    <origin
      xyz="-0.36345 0.38485 0.1257"
      rpy="0 0.2618 1.5708" />
    <parent
      link="base_link" />
    <child
      link="left_rear_ultra_link" />
    <axis
      xyz="0 0 0" />
  </joint>
  <link
    name="left_middle_ultra_link">
    <inertial>
      <origin
        xyz="0.0041766 -4.2017E-06 5.2682E-05"
        rpy="0 0 0" />
      <mass
        value="0.0062273" />
      <inertia
        ixx="1.2204E-06"
        ixy="-1.3189E-10"
        ixz="-2.0237E-09"
        iyy="2.3852E-07"
        iyz="1.9966E-10"
        izz="1.1941E-06" />
    </inertial>
    <visual>
      <origin
        xyz="0 0 0"
        rpy="0 0 0" />
      <geometry>
        <mesh
          filename="package://historia/meshes/left_middle_ultra_link.STL" />
      </geometry>
      <material
        name="">
        <color
          rgba="0.79216 0.81961 0.93333 1" />
      </material>
    </visual>
    <collision>
      <origin
        xyz="0 0 0"
        rpy="0 0 0" />
      <geometry>
        <mesh
          filename="package://historia/meshes/left_middle_ultra_link.STL" />
      </geometry>
    </collision>
  </link>
  <joint
    name="left_middle_ultra_joint"
    type="fixed">
    <origin
      xyz="-0.1172 0.4715 0.12175"
      rpy="0 0 1.5708" />
    <parent
      link="base_link" />
    <child
      link="left_middle_ultra_link" />
    <axis
      xyz="0 0 0" />
  </joint>
  <link
    name="rear_ultra_link">
    <inertial>
      <origin
        xyz="0.0041766 -4.2017E-06 5.2682E-05"
        rpy="0 0 0" />
      <mass
        value="0.0062273" />
      <inertia
        ixx="1.2204E-06"
        ixy="-1.3189E-10"
        ixz="-2.0237E-09"
        iyy="2.3852E-07"
        iyz="1.9966E-10"
        izz="1.1941E-06" />
    </inertial>
    <visual>
      <origin
        xyz="0 0 0"
        rpy="0 0 0" />
      <geometry>
        <mesh
          filename="package://historia/meshes/rear_ultra_link.STL" />
      </geometry>
      <material
        name="">
        <color
          rgba="0.79216 0.81961 0.93333 1" />
      </material>
    </visual>
    <collision>
      <origin
        xyz="0 0 0"
        rpy="0 0 0" />
      <geometry>
        <mesh
          filename="package://historia/meshes/rear_ultra_link.STL" />
      </geometry>
    </collision>
  </link>
  <joint
    name="rear_ultra_joint"
    type="fixed">
    <origin
      xyz="-0.87312 8.75E-05 0.54305"
      rpy="0 0 3.1416" />
    <parent
      link="base_link" />
    <child
      link="rear_ultra_link" />
    <axis
      xyz="0 0 0" />
  </joint>
</robot>