<?xml version="1.0" encoding="utf-8"?>
<!-- This URDF was automatically created by SolidWorks to URDF Exporter! Originally created by Stephen Brawner (brawner@gmail.com) 
     Commit Version: 1.6.0-4-g7f85cfe  Build Version: 1.6.7995.38578
     For more information, please see http://wiki.ros.org/sw_urdf_exporter -->
<robot
  xmlns:xacro="http://www.ros.org/wiki/xacro" name="historia">


<!-- Import all Gazebo-customization elements-->
  <xacro:include filename="$(find historia)/urdf/mybot.gazebo" />


   <!-- dummy link -->
        <link name="base_footprint"/>
        <joint name="dummy_joint" type="fixed">
          <origin xyz="0.0 0.0 0.0" rpy="0.0 0.0 0.0"/>
          <parent link="base_footprint"/>
          <child link="base_link"/>
          <axis xyz="0.0 0.0 0.0"/>
          <limit lower="0.0" upper="0.0" effort="0.0" velocity="0.0"/>
        </joint>

  <link
    name="base_link">
    <inertial>
      <origin
        xyz="0.0551500950716461 0.000382701697254628 0.0831948322975438"
        rpy="0 0 0" />
      <mass
        value="61.4377623129161" />
      <inertia
        ixx="6.71962689194729"
        ixy="0.000124037120014998"
        ixz="0.565316875594413"
        iyy="21.0066300839919"
        iyz="-0.0142889305150954"
        izz="21.1870326919062" />
    </inertial>
    <visual>
      <origin
        xyz="0 0 0"
        rpy="0 0 0" />
      <geometry>
        <mesh
          filename="package://historia/meshes/base_link.STL" />
      </geometry>
      <material
        name="">
        <color
          rgba="0.792156862745098 0.819607843137255 0.933333333333333 1" />
      </material>
    </visual>
    <collision>
      <origin
        xyz="0 0 0"
        rpy="0 0 0" />
      <geometry>
        <mesh
          filename="package://historia/meshes/base_link.STL" />
      </geometry>
    </collision>
  </link>
  <link
    name="front_right_wheel_link">
    <inertial>
      <origin
        xyz="-1.55431223447522E-15 0.0850000000000004 2.44249065417534E-15"
        rpy="0 0 0" />
      <mass
        value="27.5043397926287" />
      <inertia
        ixx="0.430660554325853"
        ixy="3.24890777589256E-18"
        ixz="-7.23882738820399E-18"
        iyy="0.738191606146009"
        iyz="-7.12844232875935E-20"
        izz="0.430660554325854" />
    </inertial>
    <visual>
      <origin
        xyz="0 0 0"
        rpy="0 0 0" />
      <geometry>
        <mesh
          filename="package://historia/meshes/front_right_wheel_link.STL" />
      </geometry>
      <material
        name="">
        <color
          rgba="0.792156862745098 0.819607843137255 0.933333333333333 1" />
      </material>
    </visual>
    <collision>
      <origin
        xyz="0 0 0"
        rpy="0 0 0" />
      <geometry>
        <mesh
          filename="package://historia/meshes/front_right_wheel_link.STL" />
      </geometry>
    </collision>
  </link>
  <joint
    name="front_right_wheel_joint"
    type="continuous">
    <origin
      xyz="1.0431 -0.50032 0.061"
      rpy="0 0 0" />
    <parent
      link="base_link" />
    <child
      link="front_right_wheel_link" />
    <axis
      xyz="0 1 0" />
    <limit
      effort="1000"
      velocity="1000" />
  </joint>
  <link
    name="front_left_wheel_link">
    <inertial>
      <origin
        xyz="0 -0.085 -2.22044604925031E-16"
        rpy="0 0 0" />
      <mass
        value="27.5043397926287" />
      <inertia
        ixx="0.430660554325854"
        ixy="-4.4685491471646E-18"
        ixz="-1.44592935726242E-18"
        iyy="0.738191606146009"
        iyz="-2.07712992781933E-19"
        izz="0.430660554325854" />
    </inertial>
    <visual>
      <origin
        xyz="0 0 0"
        rpy="0 0 0" />
      <geometry>
        <mesh
          filename="package://historia/meshes/front_left_wheel_link.STL" />
      </geometry>
      <material
        name="">
        <color
          rgba="0.792156862745098 0.819607843137255 0.933333333333333 1" />
      </material>
    </visual>
    <collision>
      <origin
        xyz="0 0 0"
        rpy="0 0 0" />
      <geometry>
        <mesh
          filename="package://historia/meshes/front_left_wheel_link.STL" />
      </geometry>
    </collision>
  </link>
  <joint
    name="front_left_wheel_joint"
    type="continuous">
    <origin
      xyz="1.0431 0.49993 0.061"
      rpy="0 0 0" />
    <parent
      link="base_link" />
    <child
      link="front_left_wheel_link" />
    <axis
      xyz="0 1 0" />
    <limit
      effort="1000"
      velocity="1000" />
  </joint>
  <link
    name="rear_left_wheel_link">
    <inertial>
      <origin
        xyz="0 -0.12 0"
        rpy="0 0 0" />
      <mass
        value="48.0045170814902" />
      <inertia
        ixx="1.00365544511807"
        ixy="1.23599047663348E-17"
        ixz="-1.73549109958526E-18"
        iyy="1.59552843699028"
        iyz="-1.96511643762987E-19"
        izz="1.00365544511807" />
    </inertial>
    <visual>
      <origin
        xyz="0 0 0"
        rpy="0 0 0" />
      <geometry>
        <mesh
          filename="package://historia/meshes/rear_left_wheel_link.STL" />
      </geometry>
      <material
        name="">
        <color
          rgba="0.792156862745098 0.819607843137255 0.933333333333333 1" />
      </material>
    </visual>
    <collision>
      <origin
        xyz="0 0 0"
        rpy="0 0 0" />
      <geometry>
        <mesh
          filename="package://historia/meshes/rear_left_wheel_link.STL" />
      </geometry>
    </collision>
  </link>
  <joint
    name="rear_left_wheel_joint"
    type="continuous">
    <origin
      xyz="-1.0569 0.5001 0.091"
      rpy="0 0 0" />
    <parent
      link="base_link" />
    <child
      link="rear_left_wheel_link" />
    <axis
      xyz="0 1 0" />
    <limit
      effort="1000"
      velocity="1000" />
  </joint>
  <link
    name="rear_right_wheel_link">
    <inertial>
      <origin
        xyz="0 0.12 0"
        rpy="0 0 0" />
      <mass
        value="48.0045170814902" />
      <inertia
        ixx="1.00365544511807"
        ixy="-7.15573433840433E-18"
        ixz="8.89702231972231E-19"
        iyy="1.59552843699028"
        iyz="1.78893358460108E-18"
        izz="1.00365544511807" />
    </inertial>
    <visual>
      <origin
        xyz="0 0 0"
        rpy="0 0 0" />
      <geometry>
        <mesh
          filename="package://historia/meshes/rear_right_wheel_link.STL" />
      </geometry>
      <material
        name="">
        <color
          rgba="0.792156862745098 0.819607843137255 0.933333333333333 1" />
      </material>
    </visual>
    <collision>
      <origin
        xyz="0 0 0"
        rpy="0 0 0" />
      <geometry>
        <mesh
          filename="package://historia/meshes/rear_right_wheel_link.STL" />
      </geometry>
    </collision>
  </link>
  <joint
    name="rear_right_wheel_joint"
    type="continuous">
    <origin
      xyz="-1.0569 -0.50021 0.091"
      rpy="0 0 0" />
    <parent
      link="base_link" />
    <child
      link="rear_right_wheel_link" />
    <axis
      xyz="0 1 0" />
    <limit
      effort="1000"
      velocity="1000" />
  </joint>
  <link
    name="steering_link">
    <inertial>
      <origin
        xyz="-0.00192787741428546 -9.15584132235026E-05 -0.00127138531000748"
        rpy="0 0 0" />
      <mass
        value="0.321979809173625" />
      <inertia
        ixx="0.00472741497670012"
        ixy="-2.84977472595014E-08"
        ixz="6.23081654585944E-06"
        iyy="0.00193247893753922"
        iyz="3.00788024626372E-08"
        izz="0.00286081799080933" />
    </inertial>
    <visual>
      <origin
        xyz="0 0 0"
        rpy="0 0 0" />
      <geometry>
        <mesh
          filename="package://historia/meshes/steering_link.STL" />
      </geometry>
      <material
        name="">
        <color
          rgba="0.792156862745098 0.819607843137255 0.933333333333333 1" />
      </material>
    </visual>
    <collision>
      <origin
        xyz="0 0 0"
        rpy="0 0 0" />
      <geometry>
        <mesh
          filename="package://historia/meshes/steering_link.STL" />
      </geometry>
    </collision>
  </link>
  <joint
    name="steering_joint"
    type="continuous">
    <origin
      xyz="0.28269 -0.00024936 0.44194"
      rpy="0 0 0" />
    <parent
      link="base_link" />
    <child
      link="steering_link" />
    <axis
      xyz="1 0 0" />
    <limit
      effort="5"
      velocity="0" />
  </joint>
  <link
    name="zed2_base_link">
    <inertial>
      <origin
        xyz="-0.0155625082465085 0.00050655910960673 -0.00990954357108276"
        rpy="0 0 0" />
      <mass
        value="0.0407155157147949" />
      <inertia
        ixx="3.40770206840209E-05"
        ixy="3.91387011667428E-08"
        ixz="-3.21803357293848E-07"
        iyy="1.00514941710594E-05"
        iyz="5.47911103810995E-09"
        izz="2.65392817842737E-05" />
    </inertial>
    <visual>
      <origin
        xyz="0 0 0"
        rpy="0 0 0" />
      <geometry>
        <mesh
          filename="package://historia/meshes/front_camera_link.STL" />
      </geometry>
      <material
        name="">
        <color
          rgba="0.592156862745098 0.666666666666667 0.682352941176471 1" />
      </material>
    </visual>
    <collision>
      <origin
        xyz="0 0 0"
        rpy="0 0 0" />
      <geometry>
        <mesh
          filename="package://historia/meshes/front_camera_link.STL" />
      </geometry>
    </collision>
  </link>
  <joint
    name="front_camera_joint"
    type="fixed">
    <origin
      xyz="0.0788087029649029 -0.00182333284482761 1.17208753367838"
      rpy="0 0.139626340159547 0" />
    <parent
      link="base_link" />
    <child
      link="front_camera_link" />
    <axis
      xyz="0 0 0" />
  </joint>
  <link
    name="imu_link">
    <inertial>
      <origin
        xyz="-0.00750000000000017 4.44089209850063E-16 -1.33226762955019E-15"
        rpy="0 0 0" />
      <mass
        value="0.00150000000000002" />
      <inertia
        ixx="2.50000000000007E-08"
        ixy="4.7106988573904E-25"
        ixz="1.81979734761666E-22"
        iyy="4.06250000000015E-08"
        iyz="1.14941058494395E-25"
        izz="4.06250000000001E-08" />
    </inertial>
    <visual>
      <origin
        xyz="0 0 0"
        rpy="0 0 0" />
      <geometry>
        <mesh
          filename="package://historia/meshes/imu_link.STL" />
      </geometry>
      <material
        name="">
        <color
          rgba="0.792156862745098 0.819607843137255 0.933333333333333 1" />
      </material>
    </visual>
    <collision>
      <origin
        xyz="0 0 0"
        rpy="0 0 0" />
      <geometry>
        <mesh
          filename="package://historia/meshes/imu_link.STL" />
      </geometry>
    </collision>
  </link>
  <joint
    name="imu_joint"
    type="fixed">
    <origin
      xyz="0.0765454134872336 -0.00116014639309014 1.13334716693108"
      rpy="0 0.34906585039886 0" />
    <parent
      link="base_link" />
    <child
      link="imu_link" />
    <axis
      xyz="0 0 0" />
  </joint>
  <link
    name="front_middle_ultra_link">
    <inertial>
      <origin
        xyz="0.00417658489127204 -4.20166807835187E-06 5.26817094703702E-05"
        rpy="0 0 0" />
      <mass
        value="0.00622730507584716" />
      <inertia
        ixx="1.22042836599959E-06"
        ixy="-1.31889106466305E-10"
        ixz="-2.02367223899355E-09"
        iyy="2.38520894806705E-07"
        iyz="1.99657489756067E-10"
        izz="1.19413839438469E-06" />
    </inertial>
    <visual>
      <origin
        xyz="0 0 0"
        rpy="0 0 0" />
      <geometry>
        <mesh
          filename="package://historia/meshes/front_middle_ultra_link.STL" />
      </geometry>
      <material
        name="">
        <color
          rgba="0.792156862745098 0.819607843137255 0.933333333333333 1" />
      </material>
    </visual>
    <collision>
      <origin
        xyz="0 0 0"
        rpy="0 0 0" />
      <geometry>
        <mesh
          filename="package://historia/meshes/front_middle_ultra_link.STL" />
      </geometry>
    </collision>
  </link>
  <joint
    name="front_middle_ultra_joint"
    type="fixed">
    <origin
      xyz="1.24873870035793 -1.14830916579933E-05 0.0461914067318923"
      rpy="0 0.0349065850398906 0" />
    <parent
      link="base_link" />
    <child
      link="front_middle_ultra_link" />
    <axis
      xyz="0 0 0" />
  </joint>
  <link
    name="front_left_ultra_link">
    <inertial>
      <origin
        xyz="0.00417658489127137 -4.20166807790778E-06 5.26817094701482E-05"
        rpy="0 0 0" />
      <mass
        value="0.00622730507584701" />
      <inertia
        ixx="1.22042836599956E-06"
        ixy="-1.31889106460473E-10"
        ixz="-2.02367223899537E-09"
        iyy="2.38520894806702E-07"
        iyz="1.99657489756863E-10"
        izz="1.19413839438465E-06" />
    </inertial>
    <visual>
      <origin
        xyz="0 0 0"
        rpy="0 0 0" />
      <geometry>
        <mesh
          filename="package://historia/meshes/front_left_ultra_link.STL" />
      </geometry>
      <material
        name="">
        <color
          rgba="0.792156862745098 0.819607843137255 0.933333333333333 1" />
      </material>
    </visual>
    <collision>
      <origin
        xyz="0 0 0"
        rpy="0 0 0" />
      <geometry>
        <mesh
          filename="package://historia/meshes/front_left_ultra_link.STL" />
      </geometry>
    </collision>
  </link>
  <joint
    name="front_left_ultra_joint"
    type="fixed">
    <origin
      xyz="1.24734603654632 0.170314104990994 0.0463262819667203"
      rpy="0.0879361240237073 0.150956408635872 0.530252933124556" />
    <parent
      link="base_link" />
    <child
      link="front_left_ultra_link" />
    <axis
      xyz="0 0 0" />
  </joint>
  <link
    name="front_right_ultra_link">
    <inertial>
      <origin
        xyz="0.00417658489127248 -4.20166807901801E-06 5.26817094703702E-05"
        rpy="0 0 0" />
      <mass
        value="0.00622730507584707" />
      <inertia
        ixx="1.22042836599957E-06"
        ixy="-1.31889106473966E-10"
        ixz="-2.02367223899786E-09"
        iyy="2.385208948067E-07"
        iyz="1.99657489752756E-10"
        izz="1.19413839438467E-06" />
    </inertial>
    <visual>
      <origin
        xyz="0 0 0"
        rpy="0 0 0" />
      <geometry>
        <mesh
          filename="package://historia/meshes/front_right_ultra_link.STL" />
      </geometry>
      <material
        name="">
        <color
          rgba="0.792156862745098 0.819607843137255 0.933333333333333 1" />
      </material>
    </visual>
    <collision>
      <origin
        xyz="0 0 0"
        rpy="0 0 0" />
      <geometry>
        <mesh
          filename="package://historia/meshes/front_right_ultra_link.STL" />
      </geometry>
    </collision>
  </link>
  <joint
    name="front_right_ultra_joint"
    type="fixed">
    <origin
      xyz="1.25161196518991 -0.162811315609454 0.0455740836490779"
      rpy="-0.0879361240237093 0.150956408635871 -0.53025293312457" />
    <parent
      link="base_link" />
    <child
      link="front_right_ultra_link" />
    <axis
      xyz="0 0 0" />
  </joint>
  <link
    name="left_corner_ultra_link">
    <inertial>
      <origin
        xyz="0.00417658489127315 -4.20166807835187E-06 5.26817094700371E-05"
        rpy="0 0 0" />
      <mass
        value="0.00622730507584698" />
      <inertia
        ixx="1.22042836599956E-06"
        ixy="-1.31889106467633E-10"
        ixz="-2.02367223899513E-09"
        iyy="2.38520894806699E-07"
        iyz="1.99657489753545E-10"
        izz="1.19413839438465E-06" />
    </inertial>
    <visual>
      <origin
        xyz="0 0 0"
        rpy="0 0 0" />
      <geometry>
        <mesh
          filename="package://historia/meshes/left_corner_ultra_link.STL" />
      </geometry>
      <material
        name="">
        <color
          rgba="0.792156862745098 0.819607843137255 0.933333333333333 1" />
      </material>
    </visual>
    <collision>
      <origin
        xyz="0 0 0"
        rpy="0 0 0" />
      <geometry>
        <mesh
          filename="package://historia/meshes/left_corner_ultra_link.STL" />
      </geometry>
    </collision>
  </link>
  <joint
    name="left_corner_ultra_joint"
    type="fixed">
    <origin
      xyz="0.551140320017863 0.473129883527437 0.0448767603887972"
      rpy="0 0.523598775598304 0.880452843985949" />
    <parent
      link="base_link" />
    <child
      link="left_corner_ultra_link" />
    <axis
      xyz="0 0 0" />
  </joint>
  <link
    name="right_corner_ultra_link">
    <inertial>
      <origin
        xyz="0.00417658489127026 -4.20166807857392E-06 5.26817094708143E-05"
        rpy="0 0 0" />
      <mass
        value="0.00622730507584701" />
      <inertia
        ixx="1.22042836599956E-06"
        ixy="-1.31889106467203E-10"
        ixz="-2.02367223899444E-09"
        iyy="2.38520894806699E-07"
        iyz="1.99657489752847E-10"
        izz="1.19413839438466E-06" />
    </inertial>
    <visual>
      <origin
        xyz="0 0 0"
        rpy="0 0 0" />
      <geometry>
        <mesh
          filename="package://historia/meshes/right_corner_ultra_link.STL" />
      </geometry>
      <material
        name="">
        <color
          rgba="0.792156862745098 0.819607843137255 0.933333333333333 1" />
      </material>
    </visual>
    <collision>
      <origin
        xyz="0 0 0"
        rpy="0 0 0" />
      <geometry>
        <mesh
          filename="package://historia/meshes/right_corner_ultra_link.STL" />
      </geometry>
    </collision>
  </link>
  <joint
    name="right_corner_ultra_joint"
    type="fixed">
    <origin
      xyz="0.547213586996488 -0.47572633737785 0.0448767603887954"
      rpy="0 0.523598775598303 -1.04719755119659" />
    <parent
      link="base_link" />
    <child
      link="right_corner_ultra_link" />
    <axis
      xyz="0 0 0" />
  </joint>
  <link
    name="right_middle_ultra_link">
    <inertial>
      <origin
        xyz="0.00417658489400319 -4.20166807812983E-06 5.2681704321822E-05"
        rpy="0 0 0" />
      <mass
        value="0.0062273050758472" />
      <inertia
        ixx="1.22042836599961E-06"
        ixy="-1.31889106466755E-10"
        ixz="-2.02367223899565E-09"
        iyy="2.38520894806709E-07"
        iyz="1.99657489756211E-10"
        izz="1.1941383943847E-06" />
    </inertial>
    <visual>
      <origin
        xyz="0 0 0"
        rpy="0 0 0" />
      <geometry>
        <mesh
          filename="package://historia/meshes/right_middle_ultra_link.STL" />
      </geometry>
      <material
        name="">
        <color
          rgba="0.792156862745098 0.819607843137255 0.933333333333333 1" />
      </material>
    </visual>
    <collision>
      <origin
        xyz="0 0 0"
        rpy="0 0 0" />
      <geometry>
        <mesh
          filename="package://historia/meshes/right_middle_ultra_link.STL" />
      </geometry>
    </collision>
  </link>
  <joint
    name="right_middle_ultra_joint"
    type="fixed">
    <origin
      xyz="-0.116709817139347 -0.471500000006723 0.121749999987945"
      rpy="0 0 -1.5707963267949" />
    <parent
      link="base_link" />
    <child
      link="right_middle_ultra_link" />
    <axis
      xyz="0 0 0" />
  </joint>
  <link
    name="right_rear_ultra_link">
    <inertial>
      <origin
        xyz="0.00417658489127071 -4.20166807824085E-06 5.26817094699261E-05"
        rpy="0 0 0" />
      <mass
        value="0.00622730507584708" />
      <inertia
        ixx="1.22042836599959E-06"
        ixy="-1.31889106475965E-10"
        ixz="-2.02367223899452E-09"
        iyy="2.38520894806703E-07"
        iyz="1.99657489759179E-10"
        izz="1.19413839438469E-06" />
    </inertial>
    <visual>
      <origin
        xyz="0 0 0"
        rpy="0 0 0" />
      <geometry>
        <mesh
          filename="package://historia/meshes/right_rear_ultra_link.STL" />
      </geometry>
      <material
        name="">
        <color
          rgba="0.792156862745098 0.819607843137255 0.933333333333333 1" />
      </material>
    </visual>
    <collision>
      <origin
        xyz="0 0 0"
        rpy="0 0 0" />
      <geometry>
        <mesh
          filename="package://historia/meshes/right_rear_ultra_link.STL" />
      </geometry>
    </collision>
  </link>
  <joint
    name="right_rear_ultra_joint"
    type="fixed">
    <origin
      xyz="-0.360949031132407 -0.39014057505961 0.125644556963465"
      rpy="0 0.261799387799147 -1.57079632679487" />
    <parent
      link="base_link" />
    <child
      link="right_rear_ultra_link" />
    <axis
      xyz="0 0 0" />
  </joint>
  <link
    name="left_rear_ultra_link">
    <inertial>
      <origin
        xyz="0.00417658489127248 -4.20166807851841E-06 5.26817094705923E-05"
        rpy="0 0 0" />
      <mass
        value="0.00622730507584706" />
      <inertia
        ixx="1.22042836599958E-06"
        ixy="-1.31889106456568E-10"
        ixz="-2.023672238996E-09"
        iyy="2.38520894806701E-07"
        iyz="1.99657489757113E-10"
        izz="1.19413839438468E-06" />
    </inertial>
    <visual>
      <origin
        xyz="0 0 0"
        rpy="0 0 0" />
      <geometry>
        <mesh
          filename="package://historia/meshes/left_rear_ultra_link.STL" />
      </geometry>
      <material
        name="">
        <color
          rgba="0.792156862745098 0.819607843137255 0.933333333333333 1" />
      </material>
    </visual>
    <collision>
      <origin
        xyz="0 0 0"
        rpy="0 0 0" />
      <geometry>
        <mesh
          filename="package://historia/meshes/left_rear_ultra_link.STL" />
      </geometry>
    </collision>
  </link>
  <joint
    name="left_rear_ultra_joint"
    type="fixed">
    <origin
      xyz="-0.363445190506897 0.3848471047899 0.125700254693915"
      rpy="0 0.261799387799147 1.5707963267949" />
    <parent
      link="base_link" />
    <child
      link="left_rear_ultra_link" />
    <axis
      xyz="0 0 0" />
  </joint>
  <link
    name="left_middle_ultra_link">
    <inertial>
      <origin
        xyz="0.00417658489490647 -4.20167830028628E-06 5.26817146191405E-05"
        rpy="0 0 0" />
      <mass
        value="0.00622730507584707" />
      <inertia
        ixx="1.22042836599958E-06"
        ixy="-1.31889106468567E-10"
        ixz="-2.02367223899428E-09"
        iyy="2.38520894806702E-07"
        iyz="1.9965748975306E-10"
        izz="1.19413839438467E-06" />
    </inertial>
    <visual>
      <origin
        xyz="0 0 0"
        rpy="0 0 0" />
      <geometry>
        <mesh
          filename="package://historia/meshes/left_middle_ultra_link.STL" />
      </geometry>
      <material
        name="">
        <color
          rgba="0.792156862745098 0.819607843137255 0.933333333333333 1" />
      </material>
    </visual>
    <collision>
      <origin
        xyz="0 0 0"
        rpy="0 0 0" />
      <geometry>
        <mesh
          filename="package://historia/meshes/left_middle_ultra_link.STL" />
      </geometry>
    </collision>
  </link>
  <joint
    name="left_middle_ultra_joint"
    type="fixed">
    <origin
      xyz="-0.117198877451639 0.47150000000894 0.121750000011961"
      rpy="0 0 1.5707963267949" />
    <parent
      link="base_link" />
    <child
      link="left_middle_ultra_link" />
    <axis
      xyz="0 0 0" />
  </joint>
  <link
    name="rear_ultra_link">
    <inertial>
      <origin
        xyz="0.00417658489127213 -4.20166444436987E-06 5.26817094701482E-05"
        rpy="0 0 0" />
      <mass
        value="0.00622730507584708" />
      <inertia
        ixx="1.22042836599958E-06"
        ixy="-1.31889106466113E-10"
        ixz="-2.02367223899572E-09"
        iyy="2.38520894806703E-07"
        iyz="1.99657489754901E-10"
        izz="1.19413839438467E-06" />
    </inertial>
    <visual>
      <origin
        xyz="0 0 0"
        rpy="0 0 0" />
      <geometry>
        <mesh
          filename="package://historia/meshes/rear_ultra_link.STL" />
      </geometry>
      <material
        name="">
        <color
          rgba="0.792156862745098 0.819607843137255 0.933333333333333 1" />
      </material>
    </visual>
    <collision>
      <origin
        xyz="0 0 0"
        rpy="0 0 0" />
      <geometry>
        <mesh
          filename="package://historia/meshes/rear_ultra_link.STL" />
      </geometry>
    </collision>
  </link>
  <joint
    name="rear_ultra_joint"
    type="fixed">
    <origin
      xyz="-0.873118105723869 8.75000826661143E-05 0.543051124922534"
      rpy="0 0 3.14159265358977" />
    <parent
      link="base_link" />
    <child
      link="rear_ultra_link" />
    <axis
      xyz="0 0 0" />
  </joint>
  <link
    name="rear_wheel">
    <inertial>
      <origin
        xyz="-0.000942322435045023 5.70735240006393E-05 -0.0013048342506583"
        rpy="0 0 0" />
      <mass
        value="0.375887342090846" />
      <inertia
        ixx="0.000308806943958757"
        ixy="9.03822227674029E-07"
        ixz="1.09640508272293E-05"
        iyy="0.000459797531815349"
        iyz="-1.93771977965061E-06"
        izz="0.0003119678586967" />
    </inertial>
    <visual>
      <origin
        xyz="0 0 0"
        rpy="0 0 0" />
      <geometry>
        <mesh
          filename="package://historia/meshes/rear_wheel.STL" />
      </geometry>
      <material
        name="">
        <color
          rgba="0.792156862745098 0.819607843137255 0.933333333333333 1" />
      </material>
    </visual>
    <collision>
      <origin
        xyz="0 0 0"
        rpy="0 0 0" />
      <geometry>
        <mesh
          filename="package://historia/meshes/rear_wheel.STL" />
      </geometry>
    </collision>
  </link>
  <joint
    name="rear_wheel_joint"
    type="continuous">
    <origin
      xyz="-1.0571 0 0.091"
      rpy="0 0 0" />
    <parent
      link="base_link" />
    <child
      link="rear_wheel" />
    <axis
      xyz="0 1 0" />
    <limit
      effort="1000"
      velocity="1000" />
  </joint>
  <link
    name="front_steer">
    <inertial>
      <origin
        xyz="0.0023963 0.00019764 0.025"
        rpy="0 0 0" />
      <mass
        value="0.81548" />
      <inertia
        ixx="0.0011707"
        ixy="-3.559E-19"
        ixz="0"
        iyy="0.001295"
        iyz="-1.5308E-20"
        izz="0.0011065" />
    </inertial>
    <visual>
      <origin
        xyz="0 0 0"
        rpy="0 0 0" />
      <geometry>
        <mesh
          filename="package://historia/meshes/front_steer.STL" />
      </geometry>
      <material
        name="">
        <color
          rgba="0.79216 0.81961 0.93333 1" />
      </material>
    </visual>
    <collision>
      <origin
        xyz="0 0 0"
        rpy="0 0 0" />
      <geometry>
        <mesh
          filename="package://historia/meshes/front_steer.STL" />
      </geometry>
    </collision>
  </link>
  <joint
    name="front_steer_joint"
    type="revolute">
    <origin
      xyz="1.0431 -0.00019764 0.061"
      rpy="0 0 0" />
    <parent
      link="base_link" />
    <child
      link="front_steer" />
    <axis
      xyz="0 0 1" />
    <limit
      lower="-0.8"
      upper="0.8"
      effort="1000"
      velocity="1000" />
  </joint>
  <link
    name="right_steering_hinge">
    <inertial>
      <origin
        xyz="-2.6645E-15 1.5177E-06 1.5543E-15"
        rpy="0 0 0" />
      <mass
        value="0.70472" />
      <inertia
        ixx="0.0022589"
        ixy="2.7161E-20"
        ixz="-5.3479E-21"
        iyy="0.0044118"
        iyz="-2.1196E-22"
        izz="0.0022589" />
    </inertial>
    <visual>
      <origin
        xyz="0 0 0"
        rpy="0 0 0" />
      <geometry>
        <mesh
          filename="package://historia/meshes/right_steering_hinge.STL" />
      </geometry>
      <material
        name="">
        <color
          rgba="0.79216 0.81961 0.93333 1" />
      </material>
    </visual>
    <collision>
      <origin
        xyz="0 0 0"
        rpy="0 0 0" />
      <geometry>
        <mesh
          filename="package://historia/meshes/right_steering_hinge.STL" />
      </geometry>
    </collision>
  </link>
  <joint
    name="right_steering_hinge_joint"
    type="revolute">
    <origin
      xyz="1.0431 -0.24832 0.061"
      rpy="0 0 0" />
    <parent
      link="base_link" />
    <child
      link="right_steering_hinge" />
    <axis
      xyz="0 0 -1" />
    <limit
      lower="-0.8"
      upper="0.8"
      effort="1000"
      velocity="1000" />
  </joint>
  <link
    name="left_steering_hinge">
    <inertial>
      <origin
        xyz="-2.2204E-16 0.0010015 -2.2204E-16"
        rpy="0 0 0" />
      <mass
        value="0.70472" />
      <inertia
        ixx="0.0022589"
        ixy="-6.7516E-21"
        ixz="-2.0584E-36"
        iyy="0.0044118"
        iyz="3.4169E-36"
        izz="0.0022589" />
    </inertial>
    <visual>
      <origin
        xyz="0 0 0"
        rpy="0 0 0" />
      <geometry>
        <mesh
          filename="package://historia/meshes/left_steering_hinge.STL" />
      </geometry>
      <material
        name="">
        <color
          rgba="0.79216 0.81961 0.93333 1" />
      </material>
    </visual>
    <collision>
      <origin
        xyz="0 0 0"
        rpy="0 0 0" />
      <geometry>
        <mesh
          filename="package://historia/meshes/left_steering_hinge.STL" />
      </geometry>
    </collision>
  </link>
  <joint
    name="left_steering_hinge_joint"
    type="revolute">
    <origin
      xyz="1.0431 0.24693 0.061"
      rpy="0 0 0" />
    <parent
      link="base_link" />
    <child
      link="left_steering_hinge" />
    <axis
      xyz="0 0 -1" />
    <limit
      lower="-0.8"
      upper="0.8"
      effort="1000"
      velocity="1000" />
  </joint>
  <link
    name="3D_lidar">
    <inertial>
      <origin
        xyz="0.05515 0.0003827 0.083195"
        rpy="0 0 0" />
      <mass
        value="61.438" />
      <inertia
        ixx="6.7196"
        ixy="0.00012404"
        ixz="0.56532"
        iyy="21.007"
        iyz="-0.014289"
        izz="21.187" />
    </inertial>
    <visual>
      <origin
        xyz="0 0 0"
        rpy="0 0 0" />
      <geometry>
        <mesh
          filename="package://historia/meshes/3D_lidar.STL" />
      </geometry>
      <material
        name="">
        <color
          rgba="0.79216 0.81961 0.93333 1" />
      </material>
    </visual>
    <collision>
      <origin
        xyz="0 0 0"
        rpy="0 0 0" />
      <geometry>
        <mesh
          filename="package://historia/meshes/3D_lidar.STL" />
      </geometry>
    </collision>
  </link>
  <joint
    name="3D_lidar_joint"
    type="fixed">
    <origin
      xyz="-0.23277 -0.0014942 1.21"
      rpy="0 0 0" />
    <parent
      link="base_link" />
    <child
      link="3D_lidar" />
    <axis
      xyz="0 0 0" />
  </joint>
</robot>